<?xml version="1.0" ?>
<robot name="open-chain">
    <material name="yellow">
        <color rgba="0.8 0.6 0.4 1"/>
    </material>

    <!-- ********** KINEMATIC PROPERTIES (JOINTS) ********** -->
    <joint name="world_joint" type="fixed">
        <parent link="world"/>
        <child link="base_link"/>
        <origin rpy="0.0 0.0 0.0" xyz="0.0 0.0 0.0"/>
    </joint>
    <joint name="joint1" type="revolute">
        <parent link="base_link"/>
        <child link="link1"/>
        <origin rpy="0.0 1.570796327 0.0" xyz="0.0 0.0 0.0"/>
        <axis xyz="0 1 0"/>
        <limit effort="100" velocity="1"/>
    </joint>
    <joint name="joint2" type="revolute">
        <parent link="link1"/>
        <child link="link2"/>
        <origin rpy="0.0 -1.570796327 0.0" xyz="0.5 0.0 0"/>
        <axis xyz="0 1 0"/>
        <limit effort="100" velocity="1"/>
    </joint>
    <joint name="joint3" type="revolute">
        <parent link="link2"/>
        <child link="link3"/>
        <origin rpy="0.0 1.570796327 0.0" xyz="0.5 0.0 0.0"/>
        <axis xyz="0 1 0"/>
        <limit effort="100" velocity="1"/>
    </joint>
    <joint name="ee_joint" type="fixed">
        <origin rpy="0 0 0" xyz="0.5 0.0 0.0"/>
        <parent link="link3"/>
        <child link="end_effector"/>
    </joint>

    <!-- ********** INERTIAL PROPERTIES (LINKS) ********** -->
    <link name="world"/>

    <link name="base_link" />
    <link name="link1">
        <inertial>
            <mass value="0.5"/>
            <origin rpy="0 1.570796327 0" xyz="0.25 0 0.0"/>
            <inertia ixx="0.01" iyy="0.01" izz="0.01" ixy="0.0" ixz="0.0" iyz="0.0"/>
        </inertial>

        <visual>
            <origin rpy="0 1.570796327 0" xyz="0.25 0 0.0"/>
            <geometry>
                <cylinder length="0.5" radius="0.02"/>
            </geometry>
            <material name="yellow"/>
        </visual>

    </link>
    <link name="link2">
        <inertial>
            <mass value="0.5"/>
            <origin rpy="0 1.570796327 0" xyz="0.25 0 0.0"/>
            <inertia ixx="0.01" iyy="0.01" izz="0.01" ixy="0.0" ixz="0.0" iyz="0.0"/>
        </inertial>

        <visual>
            <origin rpy="0 1.570796327 0" xyz="0.25 0 0.0"/>
            <geometry>
                <cylinder length="0.5" radius="0.02"/>
            </geometry>
            <material name="yellow"/>
        </visual>
    </link>
    <link name="link3">
        <inertial>
            <mass value="0.5"/>
            <origin rpy="0 1.570796327 0" xyz="0.25 0 0.0"/>
            <inertia ixx="0.01" iyy="0.01" izz="0.01" ixy="0.0" ixz="0.0" iyz="0.0"/>
        </inertial>

        <visual>
            <origin rpy="0 1.570796327 0" xyz="0.25 0 0.0"/>
            <geometry>
                <cylinder length="0.5" radius="0.02"/>
            </geometry>
            <material name="yellow"/>
        </visual>
    </link>

    <link name="end_effector">
        <visual>
            <origin rpy="0 0 0" xyz="0 0 0"/>
            <geometry>
                <sphere radius="0.05"/>
            </geometry>
            <material name="yellow"/>
        </visual>
    </link>
</robot>
